Workbook

Sheet ملخص البنود
A4: # | B4: الشبكة / المنشأ | C4: البند | D4: تقديم المواد | E4: اعتماد المواد | F4: أمر الشراء | G4: التصنيع | H4: أول توريد | I4: التوريد والفحص | J4: أقصى تأخير (يوم) | K4: أول مرحلة متأخرة | L4: حالة البند | M4: انتهاء التوريد في خط الاساس | N4: انتهاء التوريد المتوقع | O4: افادة المقاول | P4: Float | Q4: الوحدة | R4: الكمية الإجمالية | S4: الكمية الموردة فعلياً | T4: المتبقي (فعلي) | U4: نسبة التوريد
A5: 1 | B5: الزراعة والتنسيق | C5: Site Furnishings — Softscape and Landscape | D5: مكتمل | E5: مكتمل | F5: 256 | G5: 159 | H5: 159 | I5: 156 | J5: =MAX(D5:I5) -> 256 | K5: أمر الشراء | L5: لم يبدأ | M5: 46266 | N5: 46422 | O5: سيتم الالتزام بالتوريد خلال الموعد المحدد - فبراير 2027 | P5: =M5-N5 -> -156 | Q5: عدد | R5: 16211 | T5: =R5-S5 -> 16211
A6: 2 | B6: الزراعة والتنسيق | C6: Softscape and Planting — Softscape and Landscape | D6: مكتمل | E6: مكتمل | F6: 256 | G6: 182 | H6: 182 | I6: 175 | J6: =MAX(D6:I6) -> 256 | K6: أمر الشراء | L6: لم يبدأ | M6: 46261 | N6: 46418 | O6: سيتم الالتزام بالتوريد خلال الموعد المحدد - فبراير 2027 | P6: =M6-N6 -> -157 | Q6: م2 | R6: 18179 | T6: =R6-S6 -> 18179
A7: 3 | B7: السور | C7: Civil Works — Fence | D7: مكتمل | E7: مكتمل | F7: مكتمل | G7: مكتمل | H7: — | I7: 98 | J7: =MAX(D7:I7) -> 98 | K7: التوريد والفحص | L7: جارٍ | M7: 46203 | N7: 46301 | O7: جاري التوريد نسبة الإنجاز 30 % ، متوقع الانتهاء مع نهاية ديسمبر 2026 | P7: =M7-N7 -> -98 | Q7: م3 | R7: =SUMIFS('تفاصيل الكميات'!$G:$G,'تفاصيل الكميات'!$A:$A,$A7) -> 12500 | S7: =SUMIFS('تفاصيل الكميات'!$H:$H,'تفاصيل الكميات'!$A:$A,$A7) -> 8300 | T7: =R7-S7 -> 4200 | U7: =IF(R7=0,"",(R7-T7)/R7) -> 0.664
A8: 4 | B8: خزان المياه المعالجة (TSE) | C8: Civil Works — Storage Tank (TSE) | D8: مكتمل | E8: مكتمل | F8: 266 | G8: 184 | H8: 183 | I8: 183 | J8: =MAX(D8:I8) -> 266 | K8: أمر الشراء | L8: لم يبدأ | M8: 46179 | N8: 46362 | O8: المواد معتمدة ، التوريد في منتصف نوفمبر | P8: =M8-N8 -> -183 | Q8: عدد | R8: 1 | T8: =R8-S8 -> 1
A9: 5 | B9: خزان المياه المعالجة (TSE) | C9: Electromechanical Works — Storage Tank (TSE) | D9: مكتمل | E9: مكتمل | F9: 217 | G9: 161 | H9: — | I9: 147 | J9: =MAX(D9:I9) -> 217 | K9: أمر الشراء | L9: لم يبدأ | M9: 46349 | N9: 46494 | O9: المواد معتمدة ، التوريد في منتصف نوفمبر | P9: =M9-N9 -> -145 | Q9: عدد | R9: 1 | T9: =R9-S9 -> 1
A10: 6 | B10: شبكة إنارة الشوارع | C10: Distrubution Panel Boards — Street Lighting Network | D10: مكتمل | E10: مكتمل | F10: 256 | G10: 144 | H10: 147 | I10: 116 | J10: =MAX(D10:I10) -> 256 | K10: التوريد والفحص | L10: لم يبدأ | M10: 46316 | N10: 46432 | O10: تم الدفع ، والتوريد خلال نوفمبر | P10: =M10-N10 -> -116 | Q10: عدد | R10: 1 | T10: =R10-S10 -> 1
A11: 7 | B11: شبكة إنارة الشوارع | C11: Lighting Cables — Street Lighting Network | D11: مكتمل | E11: مكتمل | F11: 256 | G11: 171 | H11: 171 | I11: 141 | J11: =MAX(D11:I11) -> 256 | K11: التوريد والفحص | L11: لم يبدأ | M11: 46264 | N11: 46405 | O11: تم اصدار امر الشراء ، والتوريد خلال نوفمبر | P11: =M11-N11 -> -141 | Q11: عدد | R11: =SUMIFS('تفاصيل الكميات'!$G:$G,'تفاصيل الكميات'!$A:$A,$A11) -> 3399 | S11: =SUMIFS('تفاصيل الكميات'!$H:$H,'تفاصيل الكميات'!$A:$A,$A11) -> 0 | T11: =R11-S11 -> 3399 | U11: =IF(R11=0,"",(R11-T11)/R11) -> 0
A12: 8 | B12: شبكة إنارة الشوارع | C12: Lighting Fixtures — Street Lighting Network | D12: مكتمل | E12: مكتمل | F12: 256 | G12: 132 | H12: 135 | I12: 104 | J12: =MAX(D12:I12) -> 256 | K12: التوريد والفحص | L12: لم يبدأ | M12: 46341 | N12: 46445 | O12: تم الدفع ، والتوريد خلال نوفمبر | P12: =M12-N12 -> -104 | Q12: عدد | R12: =SUMIFS('تفاصيل الكميات'!$G:$G,'تفاصيل الكميات'!$A:$A,$A12) -> 77 | S12: =SUMIFS('تفاصيل الكميات'!$H:$H,'تفاصيل الكميات'!$A:$A,$A12) -> 0 | T12: =R12-S12 -> 77 | U12: =IF(R12=0,"",(R12-T12)/R12) -> 0
A13: 9 | B13: شبكة إنارة الشوارع | C13: Lighting Poles — Street Lighting Network | D13: مكتمل | E13: مكتمل | F13: 256 | G13: 159 | H13: 159 | I13: 130 | J13: =MAX(D13:I13) -> 256 | K13: التوريد والفحص | L13: لم يبدأ | M13: 46275 | N13: 46405 | O13: تم الدفع ، والتوريد خلال نوفمبر | P13: =M13-N13 -> -130 | Q13: عدد | R13: =SUMIFS('تفاصيل الكميات'!$G:$G,'تفاصيل الكميات'!$A:$A,$A13) -> 77 | S13: =SUMIFS('تفاصيل الكميات'!$H:$H,'تفاصيل الكميات'!$A:$A,$A13) -> 0 | T13: =R13-S13 -> 77 | U13: =IF(R13=0,"",(R13-T13)/R13) -> 0
A14: 10 | B14: شبكة إنارة الشوارع | C14: Lighting Poles Foundations — Street Lighting Network | D14: مكتمل | E14: مكتمل | F14: 256 | G14: 188 | H14: 188 | I14: 179 | J14: =MAX(D14:I14) -> 256 | K14: التوريد والفحص | L14: لم يبدأ | M14: 46246 | N14: 46425 | O14: تم الدفع ، والتوريد خلال نوفمبر | P14: =M14-N14 -> -179 | Q14: عدد | R14: 75 | T14: =R14-S14 -> 75 | U14: =IF(R14=0,"",(R14-T14)/R14) -> 0
A15: 11 | B15: شبكة إنارة الشوارع | C15: Cable Lugs — Street Lighting Network | D15: مكتمل | E15: مكتمل | F15: 253 | G15: 111 | H15: 114 | I15: 121 | J15: =MAX(D15:I15) -> 253 | K15: التوريد والفحص | L15: لم يبدأ | M15: 46356 | N15: 46477 | O15: تم الدفع ، والتوريد خلال نوفمبر | P15: =M15-N15 -> -121 | Q15: عدد | R15: 405 | T15: =R15-S15 -> 405 | U15: =IF(R15=0,"",(R15-T15)/R15) -> 0
A16: 12 | B16: شبكة إنارة الشوارع | C16: Fuse Boxes — Street Lighting Network | D16: مكتمل | E16: مكتمل | F16: 253 | G16: 154 | H16: 154 | I16: 154 | J16: =MAX(D16:I16) -> 253 | K16: التوريد والفحص | L16: لم يبدأ | M16: 46356 | N16: 46510 | O16: تم الدفع ، والتوريد خلال نوفمبر | P16: =M16-N16 -> -154 | Q16: عدد | R16: 75 | T16: =R16-S16 -> 75 | U16: =IF(R16=0,"",(R16-T16)/R16) -> 0
A17: 13 | B17: شبكة إنارة الشوارع | C17: Lighting Earthing — Street Lighting Network | D17: مكتمل | E17: مكتمل | F17: 253 | G17: 153 | H17: 158 | I17: 128 | J17: =MAX(D17:I17) -> 253 | K17: التوريد والفحص | L17: لم يبدأ | M17: 46334 | N17: 46462 | O17: تم الدفع ، والتوريد خلال نوفمبر | P17: =M17-N17 -> -128 | Q17: عدد | R17: 75 | T17: =R17-S17 -> 75 | U17: =IF(R17=0,"",(R17-T17)/R17) -> 0
A18: 14 | B18: شبكة الاتصالات | C18: Ducts — Telecom Network | D18: مكتمل | E18: مكتمل | F18: 256 | G18: 146 | H18: 145 | I18: 105 | J18: =MAX(D18:I18) -> 256 | K18: أمر الشراء | L18: لم يبدأ | M18: 46270 | N18: 46375 | O18: بعد صرف المستخلص | P18: =M18-N18 -> -105 | Q18: متر | R18: 5625 | T18: =R18-S18 -> 5625 | U18: =IF(R18=0,"",(R18-T18)/R18) -> 0
A19: 15 | B19: شبكة الاتصالات | C19: Manholes — Telecom Network | D19: مكتمل | E19: مكتمل | F19: 256 | G19: 153 | H19: 153 | I19: 124 | J19: =MAX(D19:I19) -> 256 | K19: أمر الشراء | L19: لم يبدأ | M19: 46281 | N19: 46405 | O19: بعد صرف المستخلص | P19: =M19-N19 -> -124 | Q19: عدد. | R19: 56 | T19: =R19-S19 -> 56 | U19: =IF(R19=0,"",(R19-T19)/R19) -> 0
A20: 16 | B20: شبكة الجهد المتوسط | C20: Medium Voltage Cables — Medium Voltage Network | D20: مكتمل | E20: مكتمل | F20: 256 | G20: 181 | H20: 180 | I20: 152 | J20: =MAX(D20:I20) -> 256 | K20: أمر الشراء | L20: لم يبدأ | M20: 46237 | N20: 46389 | O20: سيتم تقديم RFI | P20: =M20-N20 -> -152 | Q20: متر | R20: 3100 | T20: =R20-S20 -> 3100 | U20: =IF(R20=0,"",(R20-T20)/R20) -> 0
A21: 17 | B21: شبكة الجهد المتوسط | C21: Termination and Joints Kits — Medium Voltage Network | D21: مكتمل | E21: مكتمل | F21: 256 | G21: 147 | H21: 133 | I21: 142 | J21: =MAX(D21:I21) -> 256 | K21: أمر الشراء | L21: لم يبدأ | M21: 46319 | N21: 46461 | O21: سيتم تقديم RFI | P21: =M21-N21 -> -142 | Q21: - | R21: -
A22: 18 | B22: شبكة الري | C22: Valves — Irrigation Network | D22: مكتمل | E22: مكتمل | F22: 263 | G22: 172 | H22: 172 | I22: 152 | J22: =MAX(D22:I22) -> 263 | K22: أمر الشراء | L22: لم يبدأ | M22: 46260 | N22: 46412 | O22: سيتم التوريد في الموعد المحدد | P22: =M22-N22 -> -152 | Q22: عدد | R22: =SUMIFS('تفاصيل الكميات'!$G:$G,'تفاصيل الكميات'!$A:$A,$A22) -> 91 | S22: =SUMIFS('تفاصيل الكميات'!$H:$H,'تفاصيل الكميات'!$A:$A,$A22) -> 0 | T22: =R22-S22 -> 91 | U22: =IF(R22=0,"",(R22-T22)/R22) -> 0
A23: 19 | B23: شبكة الري | C23: Main Line Pipes — Irrigation Network | D23: مكتمل | E23: مكتمل | F23: جديد (بدون BL) | G23: 209 | H23: 208 | I23: 187 | J23: =MAX(D23:I23) -> 209 | K23: التوريد والفحص | L23: جارٍ | M23: 46219 | N23: 46406 | O23: سيتم التوريد في الموعد المحدد | P23: =M23-N23 -> -187 | Q23: متر | R23: =SUMIFS('تفاصيل الكميات'!$G:$G,'تفاصيل الكميات'!$A:$A,$A23) -> 5981.57 | S23: =SUMIFS('تفاصيل الكميات'!$H:$H,'تفاصيل الكميات'!$A:$A,$A23) -> 0 | T23: =R23-S23 -> 5981.57 | U23: =IF(R23=0,"",(R23-T23)/R23) -> 0
A24: 20 | B24: شبكة الصرف الصحي | C24: Manhole Covers — Sewage Network | D24: مكتمل | E24: مكتمل | F24: 256 | G24: 181 | H24: 183 | I24: 188 | J24: =MAX(D24:I24) -> 256 | K24: أمر الشراء | L24: جارٍ | M24: 46294 | N24: 46482 | O24: سيتم التوريد في الموعد المحدد | P24: =M24-N24 -> -188 | Q24: عدد | R24: 42 | S24: 42 | T24: =R24-S24 -> 0 | U24: =IF(R24=0,"",(R24-T24)/R24) -> 1
A25: 21 | B25: شبكة الصرف الصحي | C25: Pipe— Sewage Network | D25: مكتمل | E25: مكتمل | K25: التوريد والفحص | L25: منتهي | M25: 46270 | N25: 46271 | P25: =M25-N25 -> -1 | Q25: متر | R25: 1944 | S25: 1944 | T25: =R25-S25 -> 0 | U25: =IF(R25=0,"",(R25-T25)/R25) -> 1
A26: 22 | B26: شبكة الصرف الصحي | C26: Manholes — Sewage Network | D26: مكتمل | E26: مكتمل | F26: مكتمل | G26: مكتمل | H26: مكتمل | I26: 145 | J26: =MAX(D26:I26) -> 145 | K26: التوريد والفحص | L26: جارٍ | M26: 46156 | N26: 46301 | O26: تم توريد حديد التسليح وجاري الصب في الموقع | P26: =M26-N26 -> -145 | Q26: عدد | R26: =SUMIFS('تفاصيل الكميات'!$G:$G,'تفاصيل الكميات'!$A:$A,$A26) -> 2489.594 | S26: =SUMIFS('تفاصيل الكميات'!$H:$H,'تفاصيل الكميات'!$A:$A,$A26) -> 1200 | T26: =R26-S26 -> 1289.594 | U26: =IF(R26=0,"",(R26-T26)/R26) -> 0.4820063
A27: 23 | B27: شبكة المياه المعالجة (TSE) | C27: Main Line Pipes — Treated Sewage Effluent (Tse) | D27: — | E27: — | F27: 256 | G27: 200 | H27: 200 | I27: جديد (بدون BL) | J27: =MAX(D27:I27) -> 256 | K27: أمر الشراء | L27: جارٍ | M27: 46225 | N27: 46405 | O27: سيتم التوريد في الموعد المحدد | P27: =M27-N27 -> -180 | Q27: عدد | R27: =SUMIFS('تفاصيل الكميات'!$G:$G,'تفاصيل الكميات'!$A:$A,$A27) -> 0 | S27: =SUMIFS('تفاصيل الكميات'!$H:$H,'تفاصيل الكميات'!$A:$A,$A27) -> 0 | T27: =R27-S27 -> 0 | U27: =IF(R27=0,"",(R27-T27)/R27)
A28: 24 | B28: شبكة المياه المعالجة (TSE) | C28: Valves — Treated Sewage Effluent (Tse) | D28: — | E28: — | F28: 256 | G28: 153 | H28: 153 | I28: 133 | J28: =MAX(D28:I28) -> 256 | K28: أمر الشراء | L28: لم يبدأ | M28: 46272 | N28: 46405 | O28: سيتم التوريد في الموعد المحدد | P28: =M28-N28 -> -133 | Q28: عدد | R28: 42 | T28: =R28-S28 -> 42 | U28: =IF(R28=0,"",(R28-T28)/R28) -> 0
A29: 25 | B29: شبكة تصريف السيول | C29: Manholes — Storm Drainage Network | D29: مكتمل | E29: مكتمل | F29: 257 | G29: 231 | H29: — | I29: 217 | J29: =MAX(D29:I29) -> 257 | K29: أمر الشراء | L29: جارٍ | M29: 46131 | N29: 46348 | O29: تم توريد حديد التسليح وجاري الصب في الموقع | P29: =M29-N29 -> -217 | Q29: عدد | R29: =SUMIFS('تفاصيل الكميات'!$G:$G,'تفاصيل الكميات'!$A:$A,$A29) -> 0 | S29: =SUMIFS('تفاصيل الكميات'!$H:$H,'تفاصيل الكميات'!$A:$A,$A29) -> 0 | T29: =R29-S29 -> 0 | U29: =IF(R29=0,"",(R29-T29)/R29)
A30: 26 | B30: شبكة تصريف السيول | C30: Catch Basin Covers — Storm Drainage Network | D30: مكتمل | E30: مكتمل | F30: 256 | G30: 163 | H30: 163 | I30: 161 | J30: =MAX(D30:I30) -> 256 | K30: التوريد والفحص | L30: لم يبدأ | M30: 46281 | N30: 46442 | O30: تم توريد اكثر من 80 % ، إتمام التوريد خلال الشهر الجاري | P30: =M30-N30 -> -161 | Q30: عدد | R30: 195 | T30: =R30-S30 -> 195 | U30: =IF(R30=0,"",(R30-T30)/R30) -> 0
A31: 27 | B31: شبكة تصريف السيول | C31: Catch Basin Pipes — Storm Drainage Network | D31: مكتمل | E31: مكتمل | F31: 256 | G31: 239 | H31: 237 | I31: 180 | J31: =MAX(D31:I31) -> 256 | K31: التوريد والفحص | L31: منتهي | M31: 46155 | N31: 46335 | O31: تم التوريد بالكامل | P31: =M31-N31 -> -180 | Q31: م | R31: 2686.14 | S31: 2686.14 | T31: =R31-S31 -> 0 | U31: =IF(R31=0,"",(R31-T31)/R31) -> 1
A32: 28 | B32: شبكة تصريف السيول | C32: Catch Basins — Storm Drainage Network | D32: مكتمل | E32: مكتمل | F32: 256 | G32: 239 | H32: 237 | I32: 180 | J32: =MAX(D32:I32) -> 256 | K32: التوريد والفحص | L32: جارٍ | M32: 46155 | N32: 46335 | O32: جاري التصنيع ،، وسيتم بدء التوريد خلال الأسبوع القادم ،، نهاية التوريد منتصف نوفمبر | P32: =M32-N32 -> -180 | Q32: عدد | R32: =SUMIFS('تفاصيل الكميات'!$G:$G,'تفاصيل الكميات'!$A:$A,$A32) -> 0 | S32: =SUMIFS('تفاصيل الكميات'!$H:$H,'تفاصيل الكميات'!$A:$A,$A32) -> 0 | T32: =R32-S32 -> 0 | U32: =IF(R32=0,"",(R32-T32)/R32)
A33: 29 | B33: شبكة تصريف السيول | C33: Manhole Covers — Storm Drainage Network | D33: مكتمل | E33: مكتمل | F33: 256 | G33: 146 | H33: 146 | I33: 163 | J33: =MAX(D33:I33) -> 256 | K33: التوريد والفحص | L33: لم يبدأ | M33: 46300 | N33: 46463 | O33: سيتم التوريد في الموعد المحدد ، تم اصدار امر الشراء المورد مسبك الرياض | P33: =M33-N33 -> -163 | Q33: عدد | R33: 55 | T33: =R33-S33 -> 55 | U33: =IF(R33=0,"",(R33-T33)/R33) -> 0
A34: 30 | B34: شبكة تصريف السيول | C34: Main Line Pipes — Storm Drainage Network | D34: مكتمل | E34: مكتمل | F34: 252 | G34: 194 | H34: 194 | I34: 188 | J34: =MAX(D34:I34) -> 252 | K34: التوريد والفحص | L34: جارٍ | M34: 46131 | N34: 46319 | O34: تم التوريد 80 % ، اكتمال التوريد نهاية شهر أكتوبر | P34: =M34-N34 -> -188 | Q34: متر | R34: =SUMIFS('تفاصيل الكميات'!$G:$G,'تفاصيل الكميات'!$A:$A,$A34) -> 18 | S34: =SUMIFS('تفاصيل الكميات'!$H:$H,'تفاصيل الكميات'!$A:$A,$A34) -> 0 | T34: =R34-S34 -> 18 | U34: =IF(R34=0,"",(R34-T34)/R34) -> 0
A35: 31 | B35: شبكة مياه الشرب | C35: Fire Hydrants — Potable Water Network | D35: مكتمل | E35: مكتمل | F35: 256 | G35: 170 | H35: 170 | I35: 141 | J35: =MAX(D35:I35) -> 256 | K35: أمر الشراء | L35: لم يبدأ | M35: 46239 | N35: 46380 | O35: سيتم التوريد في الموعد المحدد | P35: =M35-N35 -> -141 | Q35: عدد | R35: =SUMIFS('تفاصيل الكميات'!$G:$G,'تفاصيل الكميات'!$A:$A,$A35) -> 45 | S35: =SUMIFS('تفاصيل الكميات'!$H:$H,'تفاصيل الكميات'!$A:$A,$A35) -> 0 | T35: =R35-S35 -> 45 | U35: =IF(R35=0,"",(R35-T35)/R35) -> 0
A36: 32 | B36: شبكة مياه الشرب | C36: Surface Box — Potable Water Network | D36: مكتمل | E36: مكتمل | F36: 256 | G36: 114 | H36: — | I36: — | J36: =MAX(D36:I36) -> 256 | K36: أمر الشراء | L36: لم يبدأ | M36: 46308 | N36: 46422 | O36: سيتم التوريد في الموعد المحدد | P36: =M36-N36 -> -114 | Q36: عدد | R36: =SUMIFS('تفاصيل الكميات'!$G:$G,'تفاصيل الكميات'!$A:$A,$A36) -> 47 | S36: =SUMIFS('تفاصيل الكميات'!$H:$H,'تفاصيل الكميات'!$A:$A,$A36) -> 0 | T36: =R36-S36 -> 47 | U36: =IF(R36=0,"",(R36-T36)/R36) -> 0
A37: 33 | B37: شبكة مياه الشرب | C37: Valves — Potable Water Network | D37: مكتمل | E37: مكتمل | F37: 256 | G37: 158 | H37: 158 | I37: 138 | J37: =MAX(D37:I37) -> 256 | K37: أمر الشراء | L37: لم يبدأ | M37: 46267 | N37: 46405 | O37: سيتم التوريد منتصف نوفمبر | P37: =M37-N37 -> -138 | Q37: عدد | R37: =SUMIFS('تفاصيل الكميات'!$G:$G,'تفاصيل الكميات'!$A:$A,$A37) -> 0 | S37: =SUMIFS('تفاصيل الكميات'!$H:$H,'تفاصيل الكميات'!$A:$A,$A37) -> 0 | T37: =R37-S37 -> 0 | U37: =IF(R37=0,"",(R37-T37)/R37)
A38: 34 | B38: شبكة مياه الشرب | C38: Finishes — Potable Water Network | D38: — | E38: — | F38: — | G38: — | H38: 117 | I38: 125 | J38: =MAX(D38:I38) -> 125 | K38: التوريد والفحص | L38: لم يبدأ | M38: 46345 | N38: 46470 | O38: تحت الطلب مواد التشطيب | P38: =M38-N38 -> -125 | Q38: مقطوعيه | T38: =R38-S38 -> 0 | U38: =IF(R38=0,"",(R38-T38)/R38)
A39: 35 | B39: غرفة الحارس | C39: Civil Works — Gaurd Room | D39: مكتمل | E39: مكتمل | F39: 258 | G39: 186 | H39: 180 | I39: 158 | J39: =MAX(D39:I39) -> 258 | K39: التوريد والفحص | L39: جارٍ | M39: 46210 | N39: 46368 | O39: سيتم البدء بالاعمال الأسبوع القادم بدء الحفر | P39: =M39-N39 -> -158 | Q39: مقطوعيه | R39: 1 | T39: =R39-S39 -> 1 | U39: =IF(R39=0,"",(R39-T39)/R39) -> 0
A40: 36 | B40: محطات الرفع | C40: Electromechanical Works — Lift Stations | D40: — | E40: — | F40: 217 | G40: 167 | H40: — | I40: 147 | J40: =MAX(D40:I40) -> 217 | K40: التوريد والفحص | L40: لم يبدأ | M40: 46349 | N40: 46494 | O40: تم اصدار جميع أوامر الشراء ، وجاري التوريد في الموعد المحدد | P40: =M40-N40 -> -145 | Q40: مقطوعيه | R40: 1 | T40: =R40-S40 -> 1 | U40: =IF(R40=0,"",(R40-T40)/R40) -> 0
A41: 37 | B41: محطات الرفع | C41: Civil Works — Lift Stations | D41: مكتمل | E41: مكتمل | F41: مكتمل | G41: 159 | H41: 169 | I41: 145 | J41: =MAX(D41:I41) -> 169 | K41: التصنيع | L41: لم يبدأ | M41: 46207 | N41: 46352 | O41: تحت الطلب مواد التشطيب | P41: =M41-N41 -> -145 | Q41: مقطوعيه | R41: 1 | T41: =R41-S41 -> 1 | U41: =IF(R41=0,"",(R41-T41)/R41) -> 0
A42: 38 | B42: محطات الضخ | C42: Electromechanical Works — Pump Stations | D42: مكتمل | E42: مكتمل | F42: 217 | G42: 167 | H42: — | I42: 147 | J42: =MAX(D42:I42) -> 217 | K42: التوريد والفحص | L42: لم يبدأ | M42: 46349 | N42: 46490 | O42: تم اصدار جميع أوامر الشراء ، وجاري التوريد في الموعد المحدد | P42: =M42-N42 -> -141 | Q42: مقطوعيه | R42: 1 | T42: =R42-S42 -> 1 | U42: =IF(R42=0,"",(R42-T42)/R42) -> 0
A43: 39 | B43: محطات الضخ | C43: Civil Works — Pump Stations | D43: مكتمل | E43: مكتمل | F43: مكتمل | G43: 210 | H43: 218 | I43: 207 | J43: =MAX(D43:I43) -> 218 | K43: التصنيع | L43: جارٍ | M43: 46144 | N43: 46351 | O43: تحت الطلب مواد التشطيب | P43: =M43-N43 -> -207 | Q43: مقطوعيه | R43: 1 | T43: =R43-S43 -> 1 | U43: =IF(R43=0,"",(R43-T43)/R43) -> 0
...

Sheet تفاصيل الكميات
A1: # البند | B1: البند في البروكيرومنت | C1: مصدر السطر | D1: المرجع | E1: الوصف في شيت التوريدات | F1: الوحدة | G1: الكمية الإجمالية | H1: الكمية الموردة فعلياً | I1: المتبقي (فعلي) | J1: نسبة التوريد | K1: ملاحظات
A2: 3 | B2: Civil Works — Fence | C2: ملف متابعة التوريدات (شيت 2) | D2: صف 5 | E2: FENCE PLAIN CONCRETE FOUNDATION | F2: م3 | G2: 1500 | H2: 1300 | I2: =MAX(0,G2-H2) -> 200 | J2: =IF(G2=0,"",(G2-I2)/G2) -> 0.86666667
A3: 3 | B3: Civil Works — Fence | C3: ملف متابعة التوريدات (شيت 2) | D3: صف 6 | E3: FENCE REINFORCED CONCRETE FOUNDATION | F3: م3 | G3: 11000 | H3: 7000 | I3: =MAX(0,G3-H3) -> 4000 | J3: =IF(G3=0,"",(G3-I3)/G3) -> 0.63636364
A4: 7 | B4: Lighting Cables — Street Lighting Network | C4: ملف متابعة التوريدات (شيت 2) | D4: صف 16 | E4: STREET LIGHT CABLES | F4: عدد | G4: 3399 | H4: 0 | I4: =MAX(0,G4-H4) -> 3399 | J4: =IF(G4=0,"",(G4-I4)/G4) -> 0 | K4: الوحدة في الشيت "عدد" والكمية غالباً بالمتر
A5: 8 | B5: Lighting Fixtures — Street Lighting Network | C5: ملف متابعة التوريدات (شيت 2) | D5: صف 15 | E5: STREET LIGHT FIXTURE | F5: عدد | G5: 77 | H5: 0 | I5: =MAX(0,G5-H5) -> 77 | J5: =IF(G5=0,"",(G5-I5)/G5) -> 0
A6: 9 | B6: Lighting Poles — Street Lighting Network | C6: ملف متابعة التوريدات (شيت 2) | D6: صف 14 | E6: STREET LIGHT POLES | F6: عدد | G6: 77 | H6: 0 | I6: =MAX(0,G6-H6) -> 77 | J6: =IF(G6=0,"",(G6-I6)/G6) -> 0
A7: 18 | B7: Valves — Irrigation Network | C7: MR (شيت 3) | D7: MR!131 | E7: SOLENOID VALVE 1-1/2" | F7: EACH | G7: 12 | H7: 0 | I7: =MAX(0,G7-H7) -> 12 | J7: =IF(G7=0,"",(G7-I7)/G7) -> 0
A8: 18 | B8: Valves — Irrigation Network | C8: MR (شيت 3) | D8: MR!132 | E8: SOLENOID VALVE 2" | F8: EACH | G8: 7 | H8: 0 | I8: =MAX(0,G8-H8) -> 7 | J8: =IF(G8=0,"",(G8-I8)/G8) -> 0
A9: 18 | B9: Valves — Irrigation Network | C9: MR (شيت 3) | D9: MR!133 | E9: AIR RELEASE VALVE 1.5" | F9: EACH | G9: 12 | H9: 0 | I9: =MAX(0,G9-H9) -> 12 | J9: =IF(G9=0,"",(G9-I9)/G9) -> 0
A10: 18 | B10: Valves — Irrigation Network | C10: MR (شيت 3) | D10: MR!134 | E10: AIR RELEASE VALVE 2" | F10: EACH | G10: 7 | H10: 0 | I10: =MAX(0,G10-H10) -> 7 | J10: =IF(G10=0,"",(G10-I10)/G10) -> 0
A11: 18 | B11: Valves — Irrigation Network | C11: MR (شيت 3) | D11: MR!135 | E11: QUICK COUPLING VALVE 1" INSIDE A ROUND VALVE BOX 10" SIZE WITH A MANUAL GATE VALVE HOSE SWIVEL AND KEY WITH ALL ACCESSORIES | F11: EACH | G11: 53 | H11: 0 | I11: =MAX(0,G11-H11) -> 53 | J11: =IF(G11=0,"",(G11-I11)/G11) -> 0
A12: 19 | B12: Main Line Pipes — Irrigation Network | C12: MR (شيت 3) | D12: MR!113 | E12: PIPE DIM 32 MM ( HDPE 10 BAR ) | F12: METER | G12: 3863.91 | H12: 0 | I12: =MAX(0,G12-H12) -> 3863.91 | J12: =IF(G12=0,"",(G12-I12)/G12) -> 0
A13: 19 | B13: Main Line Pipes — Irrigation Network | C13: MR (شيت 3) | D13: MR!114 | E13: PIPE DIM 40 MM ( HDPE 10 BAR ) | F13: METER | G13: 1889.47 | H13: 0 | I13: =MAX(0,G13-H13) -> 1889.47 | J13: =IF(G13=0,"",(G13-I13)/G13) -> 0
A14: 19 | B14: Main Line Pipes — Irrigation Network | C14: MR (شيت 3) | D14: MR!115 | E14: PIPE DIM 50 MM (HDPE 10 BAR) | F14: METER | G14: 228.19 | H14: 0 | I14: =MAX(0,G14-H14) -> 228.19 | J14: =IF(G14=0,"",(G14-I14)/G14) -> 0 | K14: المصدر مكتوب EACH والكمية متر فعلياً
A15: 21 | B15: Manholes — Sewage Network | C15: ملف متابعة التوريدات (شيت 2) | D15: صف 19 | E15: مناهل شبكة الصرف الصحي | F15: عدد | G15: 42 | H15: 42 | I15: =MAX(0,G15-H15) -> 0 | J15: =IF(G15=0,"",(G15-I15)/G15) -> 1
A16: 22 | B16: Main Line Pipes — Treated Sewage Effluent (Tse) | C16: MR (شيت 3) | D16: MR!139 | E16: PIPE DIM 110 MM ( HDPE 10 BAR ) | F16: METER | G16: 1172.237 | H16: 1200 | I16: =MAX(0,G16-H16) -> 0 | J16: =IF(G16=0,"",(G16-I16)/G16) -> 1
A17: 22 | B17: Main Line Pipes — Treated Sewage Effluent (Tse) | C17: MR (شيت 3) | D17: MR!140 | E17: PIPE DIM 160 MM ( HDPE 10 BAR ) | F17: METER | G17: 1227.68 | H17: 0 | I17: =MAX(0,G17-H17) -> 1227.68 | J17: =IF(G17=0,"",(G17-I17)/G17) -> 0
A18: 22 | B18: Main Line Pipes — Treated Sewage Effluent (Tse) | C18: MR (شيت 3) | D18: MR!141 | E18: PIPE DIM 200 MM ( HDPE 10 BAR ) | F18: METER | G18: 89.677 | H18: 0 | I18: =MAX(0,G18-H18) -> 89.677 | J18: =IF(G18=0,"",(G18-I18)/G18) -> 0
A19: 24 | B19: Manholes — Storm Drainage Network | C19: ملف متابعة التوريدات (شيت 2) | D19: صف 22 | E19: مناهل شبكة تصريف مياة الامطار | F19: عدد | G19: 54 | H19: 50 | I19: =MAX(0,G19-H19) -> 4 | J19: =IF(G19=0,"",(G19-I19)/G19) -> 0.92592593
A20: 27 | B20: Catch Basins — Storm Drainage Network | C20: ملف متابعة التوريدات (شيت 2) | D20: صف 20 | E20: مصائد الأمطار | F20: عدد | G20: 201 | H20: 0 | I20: =MAX(0,G20-H20) -> 201 | J20: =IF(G20=0,"",(G20-I20)/G20) -> 0
A21: 29 | B21: Main Line Pipes — Storm Drainage Network | C21: MR (شيت 3) | D21: MR!8 | E21: UPVC PIPE 315 MM , 6 M , CLASS 4 | F21: METER | G21: 2826.11 | H21: 2736 | I21: =MAX(0,G21-H21) -> 90.11 | J21: =IF(G21=0,"",(G21-I21)/G21) -> 0.96811518 | K21: محوّل من قطعة (6م) إلى متر
A22: 29 | B22: Main Line Pipes — Storm Drainage Network | C22: MR (شيت 3) | D22: MR!9 | E22: GRP PIPE DIM 400 6BAR SN5000 | F22: METER | G22: 691.29 | H22: 864 | I22: =MAX(0,G22-H22) -> 0 | J22: =IF(G22=0,"",(G22-I22)/G22) -> 1
A23: 29 | B23: Main Line Pipes — Storm Drainage Network | C23: MR (شيت 3) | D23: MR!10 | E23: STD-PIPE-DIA0500-PN6.00-SN5000-UGS | F23: METER | G23: 173 | H23: 0 | I23: =MAX(0,G23-H23) -> 173 | J23: =IF(G23=0,"",(G23-I23)/G23) -> 0
A24: 29 | B24: Main Line Pipes — Storm Drainage Network | C24: MR (شيت 3) | D24: MR!11 | E24: STD-PIPE-DIA0600-PN6.00-SN5000 | F24: METER | G24: 92 | H24: 0 | I24: =MAX(0,G24-H24) -> 92 | J24: =IF(G24=0,"",(G24-I24)/G24) -> 0
A25: 29 | B25: Main Line Pipes — Storm Drainage Network | C25: MR (شيت 3) | D25: MR!12 | E25: STD PIPE DIA0700 PN6.00 SN5000 | F25: METER | G25: 118 | H25: 168 | I25: =MAX(0,G25-H25) -> 0 | J25: =IF(G25=0,"",(G25-I25)/G25) -> 1
A26: 29 | B26: Main Line Pipes — Storm Drainage Network | C26: MR (شيت 3) | D26: MR!13 | E26: STD-PIPE-DIA0800-PN6.00-SN10000-UGS | F26: METER | G26: 362 | H26: 0 | I26: =MAX(0,G26-H26) -> 362 | J26: =IF(G26=0,"",(G26-I26)/G26) -> 0
A27: 29 | B27: Main Line Pipes — Storm Drainage Network | C27: MR (شيت 3) | D27: MR!14 | E27: STD-PIPE-DIA0900-PN6.00-SN10000-UGS | F27: METER | G27: 720 | H27: 755 | I27: =MAX(0,G27-H27) -> 0 | J27: =IF(G27=0,"",(G27-I27)/G27) -> 1
A28: 30 | B28: Fire Hydrants — Potable Water Network | C28: MR (شيت 3) | D28: MR!80 | E28: FIRE HYDRANT 6' 150MM | F28: EACH | G28: 18 | H28: 0 | I28: =MAX(0,G28-H28) -> 18 | J28: =IF(G28=0,"",(G28-I28)/G28) -> 0
A29: 31 | B29: Surface Box — Potable Water Network | C29: MR (شيت 3) | D29: MR!86 | E29: DI SURFACE BOX | F29: PC | G29: 45 | H29: 0 | I29: =MAX(0,G29-H29) -> 45 | J29: =IF(G29=0,"",(G29-I29)/G29) -> 0
A30: 32 | B30: Valves — Potable Water Network | C30: MR (شيت 3) | D30: MR!81 | E30: D.I GATE VALVE 150 MM | F30: EACH | G30: 18 | H30: 0 | I30: =MAX(0,G30-H30) -> 18 | J30: =IF(G30=0,"",(G30-I30)/G30) -> 0
A31: 32 | B31: Valves — Potable Water Network | C31: MR (شيت 3) | D31: MR!89 | E31: GATE VALVE 250 MM | F31: PC | G31: 15 | H31: 0 | I31: =MAX(0,G31-H31) -> 15 | J31: =IF(G31=0,"",(G31-I31)/G31) -> 0
A32: 32 | B32: Valves — Potable Water Network | C32: MR (شيت 3) | D32: MR!95 | E32: FLANGED GATE VALVE 100 MM | F32: PC | G32: 10 | H32: 0 | I32: =MAX(0,G32-H32) -> 10 | J32: =IF(G32=0,"",(G32-I32)/G32) -> 0
A33: 32 | B33: Valves — Potable Water Network | C33: MR (شيت 3) | D33: MR!103 | E33: DI FLANGED GATE VALVE, DN100, PN16 | F33: EACH | G33: 1 | H33: 0 | I33: =MAX(0,G33-H33) -> 1 | J33: =IF(G33=0,"",(G33-I33)/G33) -> 0
... A35: 32 | B35: Valves — Potable Water Network | C35: MR (شيت 3) | D35: MR!107 | E35: DI GATE VALVE FOR WASHING DN 100 MM, PN16 | F35: EACH | G35: 2 | H35: 0 | I35: =MAX(0,G35-H35) -> 2 | J35: =IF(G35=0,"",(G35-I35)/G35) -> 0
